Workbook

Sheet Notes
C5: Scope The IEA produced this dataset as part of efforts to track advances in carbon capture, utilisation, and storage (CCUS). It covers all CO2 capture, transport, storage, and utilisation projects worldwide that have been commissioned since the 1970s, with an announced capacity of more than 100 000 t per year (or 1000 t per year for direct air capture facilities). It includes projects with a clear emissions reduction scope, and excludes CO2 capture for utilisation pathways which bring low climate benefits (e.g. food and beverages) or which are part of the conventional industrial process (e.g. internal use for urea production), as well as use of naturally occurring CO2 for enhanced oil recovery (EOR). When the capacity is unknown, only projects with a clear commercial scope are included. If an industrial cluster has been announced, only identified CO2 capture projects within this cluster are included (i.e. it does not include the full potential capture capacity of industrial clusters for which capture sources are not specified). Capture projects for CO2 use are included as long as the source of the CO2 (i.e. capture facility) has been clearly identified. Projects are categorised by type (capture, full chain, transport, storage, CCU), sector of point source (fuel transformation, power and heat, industry, direct air capture, etc.), and fate of CO2 (dedicated storage, EOR, utilisation, unknown/unspecified). Detailed definitions for each column are available in the Definitions tab. Project announcements as of February 2024 are included. Data Data collection and processing by the IEA. All public references are available by project. Notes on how to aggregate the data are available in Aggregation notes. For any feedback or questions please contact ccsinfo@iea.org. Citation Please cite this database as: IEA (2024), CCUS Projects Database, https://www.iea.org/data-and-statistics/data-product/ccus-projects-database

Sheet Definitions_and_assumptions
B6: Country | C6: Country of project location.
B8: Project partners | C8: Includes project developers, technology providers (''tech''), and contractors, including for feasibility, front-end engineering and design (FEED), equipment procurement and construction (EPC), etc. when applicable/known.
B10: Project type
B12: Full chain | C12: Projects where CO2 is transported from one capture facility to one injection site, typically involving a single operator.
B13: Capture | C13: Capture-only project (project does not include any transport and storage development but can be developed as part of a CCUS hub).
B14: Transport | C14: CO2 transport-only project, which may include CO2 shipping, pipelines, terminals with liquefaction stations/buffer storage, etc.
B15: Storage | C15: CO2 storage-only project (no mention of connecting infrastructure), including both dedicated storage and CO2 enhanced oil recovery (EOR).
B16: T&S | C16: CO2 transport and storage project which includes both transport and storage development.
B17: CCU | C17: A project that captures CO2 for use (excluding internal use such as urea production) with significant climate benefits and a clearly identified source for the captured CO2.
B19: Dates
B21: Announcement | C21: Year of project announcement.
B22: FID | C22: Actual or planned year of final investment decision (FID).
B23: Operation | C23: Actual or planned year of project commissioning.
B24: Suspension/decommissioning | C24: Actual year of suspension/decommissioning.
B26: Project status
B28: Planned | C28: Project at concept, feasibility or engineering study (FEED) stage. Concept projects include announcements with little to no further information available (e.g. capture technology, site, stakeholders, budget, timeline).
B29: Under construction | C29: A final investment decision (FID) has been announced and construction is ongoing or imminent.
B30: Operational | C30: Project has been commissioned and is running.
B31: Suspended | C31: Project operation is suspended for more than six months.
B32: Decommissioned | C32: Project operation is permanently stopped.
B34: Project Phase | C34: If projects have defined announced phases or plan to develop capacity in a stepwise manner, this column is used. Phasing starts from 1. Announced capacity across phases is additional, not cumulative.
B36: Announced capacity (Mt CO2 per year) | C36: Announced or actual capture, transport and/or storage CO2 capacity, in Mt CO2 per year. When capture capacity is announced as a range, or several values are available, announced capacity is entered as a range.
B38: Estimated capacity by IEA (Mt CO2 per year) | C38: Estimated capture capacity based on other plant details (e.g. fuel production capacity) or potential deployment plans. See conversion factors for further assumptions.
B40: Sector | C40: These sector categories will be published in the online version. For capture, full chain, and CCU projects, the sector corresponds to the source of capture.
B42: Power and heat | C42: Capture, full chain, and CCU projects which capture CO2 from power and heat facilities (includes waste-to-energy plants).
B43: Natural gas processing/LNG | C43: Capture, full chain, and CCU projects which capture CO2 from natural gas processing and liquefied natural gas (LNG) trains.
B44: Biofuels | C44: Capture, full chain, and CCU projects which capture CO2 from bioethanol, biodiesel, and biogas facilities.
... B54: T&S | C54: CO2 transport and storage project.
B56: Fate of carbon
B58: Dedicated storage | C58: CO2 is injected deep underground and stored permanently in a dedicated storage site.
B59: EOR | C59: CO2 is used for enhanced oil recovery.
B60: Use | C60: CO2 is used in a product with significant climate benefits. Internal use (e.g. CO2 capture and use in urea production) is excluded.
B61: Unknown/unspecified | C61: Fate of carbon has not been communicated.
B63: Part of CCUS hub
B65: If a capture, transport or storage project is developed as part of a CCUS hub (capture facilities connected to a network of CO2 storage sites by shared transport infrastructure), the name of the corresponding hub is indicated.
B67: Total capture capacity (Mt CO2 per year) | C67: sum (Estimated capacity) for full chain (''Full chain''), capture (''Capture'') and utilisation ("CCU") projects across phases, excluding suspended and decommissioned projects.
B69: Total storage capacity (Mt CO2 per year) | C69: sum (Estimated capacity) for full chain (''Full chain''), transport and storage (''T&S''), and storage (''Storage'') projects across phases, excluding suspended and decommissioned projects.
B71: Number of capture facilities | C71: count full chain (''Full chain''), capture (''Capture''), and utilisation ("CCU") projects excluding phases 2, 3, and 4, and suspended and decommissioned projects.
B73: Important note on transport: | C73: transport capacity of individual projects is not cumulative and cannot be summed.
B75: Conversion factors | C75: For projects when CO2 captured capacity is not provided but other details are provided e.g. fuel production capacity (hydrogen, ammonia, e-fuel), captured capacity can be estimated by IEA using the following assumptions:
...

Sheet Aggregation_notes
B6: Total capture capacity (Mt CO2 per year) | C6: sum (Estimated capacity) for full chain (''Full chain''), capture (''Capture'') and utilisation ("CCU") projects across phases, excluding suspended and decommissioned projects.
B8: Total storage capacity (Mt CO2 per year) | C8: sum (Estimated capacity) for full chain (''Full chain''), transport and storage (''T&S''), and storage (''Storage'') projects across phases, excluding suspended and decommissioned projects.
B10: Number of capture facilities | C10: count full chain (''Full chain''), capture (''Capture''), and utilisation ("CCU") projects excluding phases 2, 3, and 4, and suspended and decommissioned projects.
B12: Important note on transport: | C12: transport capacity of individual projects is not cumulative and cannot be summed.

Sheet CCUS_Projects_Database
A1: Project name | B1: ID | C1: Country | D1: Partners | E1: Project type | F1: Announcement | G1: FID | H1: Operation | I1: Suspension/decommissioning | J1: Project Status | K1: Project phase | L1: Announced capacity (Mt CO2/yr) | M1: Estimated capacity by IEA (Mt CO2/yr) | N1: Sector | O1: Fate of carbon | P1: Part of CCUS hub | Q1: Region | R1: Ref 1 | S1: Ref 2 | T1: Ref 3 | U1: Ref 4 | V1: Ref 5 | W1: Ref 6 | X1: Ref 7 | Y1: Link 1 | Z1: Link 2 | AA1: Link 3 | AB1: Link 4 | AC1: Link 5 | AD1: Link 6 | AE1: Link 7
A2: 3D DMX ArcelorMittal and IFPEN Dunkirk 'REUZE' | B2: 751 | C2: France | D2: ArcelorMittal, Engie, Infinium | E2: CCU | F2: 2022 | G2: 2024 | H2: 2025 | J2: Planned | K2: 1 | L2: 0.3 | M2: 0.3 | N2: Iron and steel | O2: Use | Q2: Europe | R2: https://newsroom.engie.com/actualites/engie-et-infinium-annoncent-un-partenariat-pour-developper-un-hub-industriel-denvergure-europeenne-de-production-de-carburants-de-synthese-a-dunkerque-6d4d-ff316.html | S2: https://corporate.arcelormittal.com/climate-action/decarbonisation-technologies/the-3d-project-dmx-demonstration-in-dunkirk | Y2: =IF(CCUS_Projects_Database!$R3<>"",HYPERLINK(CCUS_Projects_Database!$R3,"Link 1"),"") -> Link 1 | Z2: =IF(CCUS_Projects_Database!$S3<>"",HYPERLINK(CCUS_Projects_Database!$S3,"Link 2"),"") -> Link 2 | AA2: =IF(CCUS_Projects_Database!$T3<>"",HYPERLINK(CCUS_Projects_Database!$T3,"Link 3"),"") | AB2: =IF(CCUS_Projects_Database!$U3<>"",HYPERLINK(CCUS_Projects_Database!$U3,"Link 4"),"") | AC2: =IF(CCUS_Projects_Database!$V3<>"",HYPERLINK(CCUS_Projects_Database!$V3,"Link 5"),"") | AD2: =IF(CCUS_Projects_Database!$W3<>"",HYPERLINK(CCUS_Projects_Database!$W3,"Link 6"),"") | AE2: =IF(CCUS_Projects_Database!$X3<>"",HYPERLINK(CCUS_Projects_Database!$X3,"Link 7"),"")
A3: 3D DMX ArcelorMittal and IFPEN Dunkirk (full-scale) | B3: 1 | C3: France | D3: ArcelorMittal, ifp, Axens, Uetikon, Grassco, brevik, TotalEnergies (T&S) | E3: Capture | F3: 2019 | H3: 2025 | J3: Planned | K3: 2 | L3: 0.7 | M3: 0.7 | N3: Iron and steel | O3: Unknown/unspecified | Q3: Europe | R3: https://automotive.arcelormittal.com/news_and_stories/news/2019DMXproject | S3: https://3d-ccus.com/3d-overview/ | Y3: =IF(CCUS_Projects_Database!$R2<>"",HYPERLINK(CCUS_Projects_Database!$R2,"Link 1"),"") -> Link 1 | Z3: =IF(CCUS_Projects_Database!$S2<>"",HYPERLINK(CCUS_Projects_Database!$S2,"Link 2"),"") -> Link 2 | AA3: =IF(CCUS_Projects_Database!$T2<>"",HYPERLINK(CCUS_Projects_Database!$T2,"Link 3"),"") | AB3: =IF(CCUS_Projects_Database!$U2<>"",HYPERLINK(CCUS_Projects_Database!$U2,"Link 4"),"") | AC3: =IF(CCUS_Projects_Database!$V2<>"",HYPERLINK(CCUS_Projects_Database!$V2,"Link 5"),"") | AD3: =IF(CCUS_Projects_Database!$W2<>"",HYPERLINK(CCUS_Projects_Database!$W2,"Link 6"),"") | AE3: =IF(CCUS_Projects_Database!$X2<>"",HYPERLINK(CCUS_Projects_Database!$X2,"Link 7"),"")
A4: 7 Blue Ammonia Facility | B4: 1055 | C4: Qatar | D4: QAFCO, thyssenkrupp Uhde/Consolidated Contractors Company (EPC) | E4: Full Chain | F4: 2022 | G4: 2022 | H4: 2026 | J4: Under construction | L4: 1.5 | M4: 1.5 | N4: Hydrogen or ammonia | O4: Unknown/unspecified | Q4: Middle East | R4: https://www.qafco.qa/content/qafco-7-announcement | S4: https://www.thyssenkrupp.com/en/newsroom/press-releases/pressdetailpage/thyssenkrupp-uhde-to-build-world-scale-blue-ammonia-plant-in-qatar-138369 | Y4: =IF(CCUS_Projects_Database!$R4<>"",HYPERLINK(CCUS_Projects_Database!$R4,"Link 1"),"") -> Link 1 | Z4: =IF(CCUS_Projects_Database!$S4<>"",HYPERLINK(CCUS_Projects_Database!$S4,"Link 2"),"") -> Link 2 | AA4: =IF(CCUS_Projects_Database!$T4<>"",HYPERLINK(CCUS_Projects_Database!$T4,"Link 3"),"") | AB4: =IF(CCUS_Projects_Database!$U4<>"",HYPERLINK(CCUS_Projects_Database!$U4,"Link 4"),"") | AC4: =IF(CCUS_Projects_Database!$V4<>"",HYPERLINK(CCUS_Projects_Database!$V4,"Link 5"),"") | AD4: =IF(CCUS_Projects_Database!$W4<>"",HYPERLINK(CCUS_Projects_Database!$W4,"Link 6"),"") | AE4: =IF(CCUS_Projects_Database!$X4<>"",HYPERLINK(CCUS_Projects_Database!$X4,"Link 7"),"")
A5: 8Rivers H2 (8RH2) (WY) | B5: 3 | C5: United States | D5: 8Rivers, Wyoming Energy Authority | E5: Capture | F5: 2022 | J5: Planned | N5: Hydrogen or ammonia | O5: Dedicated storage | Q5: North America | R5: https://8rivers.com/portfolio/8-rivers-hydrogen/# | Y5: =IF(CCUS_Projects_Database!$R5<>"",HYPERLINK(CCUS_Projects_Database!$R5,"Link 1"),"") -> Link 1 | Z5: =IF(CCUS_Projects_Database!$S5<>"",HYPERLINK(CCUS_Projects_Database!$S5,"Link 2"),"") | AA5: =IF(CCUS_Projects_Database!$T5<>"",HYPERLINK(CCUS_Projects_Database!$T5,"Link 3"),"") | AB5: =IF(CCUS_Projects_Database!$U5<>"",HYPERLINK(CCUS_Projects_Database!$U5,"Link 4"),"") | AC5: =IF(CCUS_Projects_Database!$V5<>"",HYPERLINK(CCUS_Projects_Database!$V5,"Link 5"),"") | AD5: =IF(CCUS_Projects_Database!$W5<>"",HYPERLINK(CCUS_Projects_Database!$W5,"Link 6"),"") | AE5: =IF(CCUS_Projects_Database!$X5<>"",HYPERLINK(CCUS_Projects_Database!$X5,"Link 7"),"")
A6: Abadi CCS/CCUS | B6: 227 | C6: Indonesia | D6: Inpex Masela 65%, Shell (trying to find a buyer for its shares), ITB (feasibility) | E6: Full chain | F6: 2018 | H6: 2027 | J6: Planned | L6: 2.41 | M6: 2.41 | N6: Natural gas processing/LNG | O6: Unknown/unspecified | Q6: Other Asia Pacific | R6: https://www.upstreamonline.com/lng/inpex-further-delays-flagship-abadi-lng-project/2-1-1173044 | S6: https://www.ogj.com/pipelines-transportation/lng/article/14292056/inpex-submits-ccs-plan-for-abadi-lng-project | T6: https://www.spglobal.com/commodityinsights/en/market-insights/latest-news/lng/092823-interview-indonesia-to-finalize-presidential-ccsccus-regulation-by-year-end | Y6: =IF(CCUS_Projects_Database!$R6<>"",HYPERLINK(CCUS_Projects_Database!$R6,"Link 1"),"") -> Link 1 | Z6: =IF(CCUS_Projects_Database!$S6<>"",HYPERLINK(CCUS_Projects_Database!$S6,"Link 2"),"") -> Link 2 | AA6: =IF(CCUS_Projects_Database!$T6<>"",HYPERLINK(CCUS_Projects_Database!$T6,"Link 3"),"") -> Link 3 | AB6: =IF(CCUS_Projects_Database!$U6<>"",HYPERLINK(CCUS_Projects_Database!$U6,"Link 4"),"") | AC6: =IF(CCUS_Projects_Database!$V6<>"",HYPERLINK(CCUS_Projects_Database!$V6,"Link 5"),"") | AD6: =IF(CCUS_Projects_Database!$W6<>"",HYPERLINK(CCUS_Projects_Database!$W6,"Link 6"),"") | AE6: =IF(CCUS_Projects_Database!$X6<>"",HYPERLINK(CCUS_Projects_Database!$X6,"Link 7"),"")
A7: Ackerman Combined Cycle Plant (MS) | B7: 975 | C7: United States | D7: Trifecta Renewable Solutions, Tennessee Valley Authority | E7: Capture | F7: 2023 | J7: Planned | L7: 1.8 | M7: 1.8 | N7: Power and heat | O7: Dedicated storage | P7: Red Hills CO2 storage hub (MS) | Q7: North America | R7: https://www.energy.gov/fecm/project-selections-foa-2711-carbon-storage-validation-and-testing-round-2 | Y7: =IF(CCUS_Projects_Database!$R7<>"",HYPERLINK(CCUS_Projects_Database!$R7,"Link 1"),"") -> Link 1 | Z7: =IF(CCUS_Projects_Database!$S7<>"",HYPERLINK(CCUS_Projects_Database!$S7,"Link 2"),"") | AA7: =IF(CCUS_Projects_Database!$T7<>"",HYPERLINK(CCUS_Projects_Database!$T7,"Link 3"),"") | AB7: =IF(CCUS_Projects_Database!$U7<>"",HYPERLINK(CCUS_Projects_Database!$U7,"Link 4"),"") | AC7: =IF(CCUS_Projects_Database!$V7<>"",HYPERLINK(CCUS_Projects_Database!$V7,"Link 5"),"") | AD7: =IF(CCUS_Projects_Database!$W7<>"",HYPERLINK(CCUS_Projects_Database!$W7,"Link 6"),"") | AE7: =IF(CCUS_Projects_Database!$X7<>"",HYPERLINK(CCUS_Projects_Database!$X7,"Link 7"),"")
A8: Acorn CCS phase 1-Capture at St Fergus | B8: 7 | C8: United Kingdom | D8: Storegga(30%), Shell (30%), Harbour (30%), North Sea Midstream partners (10%) | E8: Capture | F8: 2016 | G8: 2024 | H8: 2028 | J8: Planned | L8: 0.3 | M8: 0.3 | N8: Natural gas processing/LNG | O8: Dedicated storage | P8: Acorn CCS | Q8: Europe | R8: https://www.upstreamonline.com/energy-transition/five-proposed-uk-carbon-capture-projects-meet-governments-eligibility-test/2-1-1047222 | S8: https://www.offshore-energy.biz/carbon-clean-to-carry-out-feed-on-acorn-carbon-capture-plant/ | T8: https://www.backthescottishcluster.co.uk/the-scottish-cluster-supply-chain | U8: https://www.storegga.earth/news/2021/news/acorn-project-partners-storegga-shell-u-k-and-harbour-energy-sign-mou-with-the-owners-of-the-segal-and-fuka-gas-terminals-at-st-fergus/ | V8: https://www.scottishconstructionnow.com/articles/acorn-project-partners-select-carbon-clean-to-deliver-st-fergus-carbon-capture-plant-feed-study | W8: https://www.energyvoice.com/oilandgas/north-sea/370332/st-fergus-terminal-owner-joins-acorn-ccs-project-as-partner | Y8: =IF(CCUS_Projects_Database!$R8<>"",HYPERLINK(CCUS_Projects_Database!$R8,"Link 1"),"") -> Link 1 | Z8: =IF(CCUS_Projects_Database!$S8<>"",HYPERLINK(CCUS_Projects_Database!$S8,"Link 2"),"") -> Link 2 | AA8: =IF(CCUS_Projects_Database!$T8<>"",HYPERLINK(CCUS_Projects_Database!$T8,"Link 3"),"") -> Link 3 | AB8: =IF(CCUS_Projects_Database!$U8<>"",HYPERLINK(CCUS_Projects_Database!$U8,"Link 4"),"") -> Link 4 | AC8: =IF(CCUS_Projects_Database!$V8<>"",HYPERLINK(CCUS_Projects_Database!$V8,"Link 5"),"") -> Link 5 | AD8: =IF(CCUS_Projects_Database!$W8<>"",HYPERLINK(CCUS_Projects_Database!$W8,"Link 6"),"") -> Link 6 | AE8: =IF(CCUS_Projects_Database!$X8<>"",HYPERLINK(CCUS_Projects_Database!$X8,"Link 7"),"")
A9: Acorn CCS phase 1-T&S | B9: 8 | C9: United Kingdom | D9: Storegga(30%), Shell (30%), Harbour (30%), North Sea Midstream partners (10%) | E9: T&S | F9: 2016 | G9: 2024 | H9: 2028 | J9: Planned | K9: 1 | L9: 0.55 | M9: 0.8 | N9: T&S | O9: Dedicated storage | P9: Acorn CCS | Q9: Europe | R9: https://www.upstreamonline.com/energy-transition/five-proposed-uk-carbon-capture-projects-meet-governments-eligibility-test/2-1-1047222 | S9: https://www.offshore-energy.biz/carbon-clean-to-carry-out-feed-on-acorn-carbon-capture-plant/ | T9: https://www.backthescottishcluster.co.uk/the-scottish-cluster-supply-chain | U9: https://www.storegga.earth/news/2021/news/acorn-project-partners-storegga-shell-u-k-and-harbour-energy-sign-mou-with-the-owners-of-the-segal-and-fuka-gas-terminals-at-st-fergus/ | V9: https://www.scottishconstructionnow.com/articles/acorn-project-partners-select-carbon-clean-to-deliver-st-fergus-carbon-capture-plant-feed-study | W9: https://www.energyvoice.com/oilandgas/north-sea/370332/st-fergus-terminal-owner-joins-acorn-ccs-project-as-partner | Y9: =IF(CCUS_Projects_Database!$R9<>"",HYPERLINK(CCUS_Projects_Database!$R9,"Link 1"),"") -> Link 1 | Z9: =IF(CCUS_Projects_Database!$S9<>"",HYPERLINK(CCUS_Projects_Database!$S9,"Link 2"),"") -> Link 2 | AA9: =IF(CCUS_Projects_Database!$T9<>"",HYPERLINK(CCUS_Projects_Database!$T9,"Link 3"),"") -> Link 3 | AB9: =IF(CCUS_Projects_Database!$U9<>"",HYPERLINK(CCUS_Projects_Database!$U9,"Link 4"),"") -> Link 4 | AC9: =IF(CCUS_Projects_Database!$V9<>"",HYPERLINK(CCUS_Projects_Database!$V9,"Link 5"),"") -> Link 5 | AD9: =IF(CCUS_Projects_Database!$W9<>"",HYPERLINK(CCUS_Projects_Database!$W9,"Link 6"),"") -> Link 6 | AE9: =IF(CCUS_Projects_Database!$X9<>"",HYPERLINK(CCUS_Projects_Database!$X9,"Link 7"),"")
A10: Acorn CCS phase 2 | B10: 9 | C10: United Kingdom | D10: Storegga(30%), Shell (30%), Harbour (30%), North Sea Midstream partners (10%) | E10: T&S | F10: 2017 | J10: Planned | K10: 2 | L10: 5 | M10: 5 | N10: T&S | O10: Dedicated storage | P10: Acorn CCS | Q10: Europe | R10: https://www.upstreamonline.com/energy-transition/five-proposed-uk-carbon-capture-projects-meet-governments-eligibility-test/2-1-1047222 | S10: https://www.offshore-energy.biz/carbon-clean-to-carry-out-feed-on-acorn-carbon-capture-plant/ | T10: https://www.backthescottishcluster.co.uk/the-scottish-cluster-supply-chain | U10: https://www.storegga.earth/news/2021/news/acorn-project-partners-storegga-shell-u-k-and-harbour-energy-sign-mou-with-the-owners-of-the-segal-and-fuka-gas-terminals-at-st-fergus/ | V10: https://www.scottishconstructionnow.com/articles/acorn-project-partners-select-carbon-clean-to-deliver-st-fergus-carbon-capture-plant-feed-study | W10: https://www.energyvoice.com/oilandgas/north-sea/370332/st-fergus-terminal-owner-joins-acorn-ccs-project-as-partner | X10: https://www.theacornproject.uk/news-and-events/nsta-grants-carbon-storage-licences-to-acorn | Y10: =IF(CCUS_Projects_Database!$R10<>"",HYPERLINK(CCUS_Projects_Database!$R10,"Link 1"),"") -> Link 1 | Z10: =IF(CCUS_Projects_Database!$S10<>"",HYPERLINK(CCUS_Projects_Database!$S10,"Link 2"),"") -> Link 2 | AA10: =IF(CCUS_Projects_Database!$T10<>"",HYPERLINK(CCUS_Projects_Database!$T10,"Link 3"),"") -> Link 3 | AB10: =IF(CCUS_Projects_Database!$U10<>"",HYPERLINK(CCUS_Projects_Database!$U10,"Link 4"),"") -> Link 4 | AC10: =IF(CCUS_Projects_Database!$V10<>"",HYPERLINK(CCUS_Projects_Database!$V10,"Link 5"),"") -> Link 5 | AD10: =IF(CCUS_Projects_Database!$W10<>"",HYPERLINK(CCUS_Projects_Database!$W10,"Link 6"),"") -> Link 6 | AE10: =IF(CCUS_Projects_Database!$X10<>"",HYPERLINK(CCUS_Projects_Database!$X10,"Link 7"),"") -> Link 7
A11: Acorn H2 | B11: 10 | C11: United Kingdom | D11: Storegga, Chrysaor, Shell | E11: Capture | F11: 2018 | H11: 2028 | J11: Planned | L11: 0.4 | M11: 0.4 | N11: Hydrogen or ammonia | O11: Dedicated storage | P11: Acorn CCS | Q11: Europe | R11: https://assets.publishing.service.gov.uk/government/uploads/system/uploads/attachment_data/file/866380/Phase_1_-_Pale_Blue_Dot_Energy_-_Acorn_Hydrogen.pdf | Y11: =IF(CCUS_Projects_Database!$R11<>"",HYPERLINK(CCUS_Projects_Database!$R11,"Link 1"),"") -> Link 1 | Z11: =IF(CCUS_Projects_Database!$S11<>"",HYPERLINK(CCUS_Projects_Database!$S11,"Link 2"),"") | AA11: =IF(CCUS_Projects_Database!$T11<>"",HYPERLINK(CCUS_Projects_Database!$T11,"Link 3"),"") | AB11: =IF(CCUS_Projects_Database!$U11<>"",HYPERLINK(CCUS_Projects_Database!$U11,"Link 4"),"") | AC11: =IF(CCUS_Projects_Database!$V11<>"",HYPERLINK(CCUS_Projects_Database!$V11,"Link 5"),"") | AD11: =IF(CCUS_Projects_Database!$W11<>"",HYPERLINK(CCUS_Projects_Database!$W11,"Link 6"),"") | AE11: =IF(CCUS_Projects_Database!$X11<>"",HYPERLINK(CCUS_Projects_Database!$X11,"Link 7"),"")
A12: Acorn Isle of Grain to Peterhead shipping | B12: 1018 | C12: United Kingdom | D12: Acorn, Uniper | E12: Transport | F12: 2023 | J12: Planned | L12: 2 | M12: 2 | N12: Transport | O12: Dedicated storage | P12: Acorn CCS | Q12: Europe | R12: https://netl.doe.gov/coal/carbon-storage/atlas/secarb | Y12: =IF(CCUS_Projects_Database!$R12<>"",HYPERLINK(CCUS_Projects_Database!$R12,"Link 1"),"") -> Link 1 | Z12: =IF(CCUS_Projects_Database!$S12<>"",HYPERLINK(CCUS_Projects_Database!$S12,"Link 2"),"") | AA12: =IF(CCUS_Projects_Database!$T12<>"",HYPERLINK(CCUS_Projects_Database!$T12,"Link 3"),"") | AB12: =IF(CCUS_Projects_Database!$U12<>"",HYPERLINK(CCUS_Projects_Database!$U12,"Link 4"),"") | AC12: =IF(CCUS_Projects_Database!$V12<>"",HYPERLINK(CCUS_Projects_Database!$V12,"Link 5"),"") | AD12: =IF(CCUS_Projects_Database!$W12<>"",HYPERLINK(CCUS_Projects_Database!$W12,"Link 6"),"") | AE12: =IF(CCUS_Projects_Database!$X12<>"",HYPERLINK(CCUS_Projects_Database!$X12,"Link 7"),"")
A13: Adams Fork Energy clean ammonia project (WV) | B13: 1033 | C13: United States | D13: Adams Fork Energy, the Flandreau Santee Sioux Tribe | E13: Capture | F13: 2022 | G13: 2024 | J13: Planned | M13: 3.591 | N13: Hydrogen or ammonia | O13: Unknown/unspecified | Q13: North America | R13: https://adamsforkenergy.com/ | S13: https://investors.cnx.com/news-releases/2023/04-03-2023-114519172 | T13: https://www.reuters.com/sustainability/cnx-resources-pulls-out-adams-fork-ammonia-project-2023-12-15/ | Y13: =IF(CCUS_Projects_Database!$R13<>"",HYPERLINK(CCUS_Projects_Database!$R13,"Link 1"),"") -> Link 1 | Z13: =IF(CCUS_Projects_Database!$S13<>"",HYPERLINK(CCUS_Projects_Database!$S13,"Link 2"),"") -> Link 2 | AA13: =IF(CCUS_Projects_Database!$T13<>"",HYPERLINK(CCUS_Projects_Database!$T13,"Link 3"),"") -> Link 3 | AB13: =IF(CCUS_Projects_Database!$U13<>"",HYPERLINK(CCUS_Projects_Database!$U13,"Link 4"),"") | AC13: =IF(CCUS_Projects_Database!$V13<>"",HYPERLINK(CCUS_Projects_Database!$V13,"Link 5"),"") | AD13: =IF(CCUS_Projects_Database!$W13<>"",HYPERLINK(CCUS_Projects_Database!$W13,"Link 6"),"") | AE13: =IF(CCUS_Projects_Database!$X13<>"",HYPERLINK(CCUS_Projects_Database!$X13,"Link 7"),"")
A14: Adbri Project | B14: 11 | C14: Australia | D14: Adbri, CarbonTP, Heavy Industry Low Emissions Technology Co-Operative Research Centre | E14: Capture | F14: 2021 | J14: Planned | N14: Cement | O14: Dedicated storage | P14: South West Hub Project | Q14: Australia and New Zealand | R14: https://calix.global/co2-mitigation-focus-area/awarded-11m-in-government-funding-for-low-emissions-lime-project-with-adbri/ | Y14: =IF(CCUS_Projects_Database!$R14<>"",HYPERLINK(CCUS_Projects_Database!$R14,"Link 1"),"") -> Link 1 | Z14: =IF(CCUS_Projects_Database!$S14<>"",HYPERLINK(CCUS_Projects_Database!$S14,"Link 2"),"") | AA14: =IF(CCUS_Projects_Database!$T14<>"",HYPERLINK(CCUS_Projects_Database!$T14,"Link 3"),"") | AB14: =IF(CCUS_Projects_Database!$U14<>"",HYPERLINK(CCUS_Projects_Database!$U14,"Link 4"),"") | AC14: =IF(CCUS_Projects_Database!$V14<>"",HYPERLINK(CCUS_Projects_Database!$V14,"Link 5"),"") | AD14: =IF(CCUS_Projects_Database!$W14<>"",HYPERLINK(CCUS_Projects_Database!$W14,"Link 6"),"") | AE14: =IF(CCUS_Projects_Database!$X14<>"",HYPERLINK(CCUS_Projects_Database!$X14,"Link 7"),"")
A15: ADM Cedar rapids bioethanol (IA) | B15: 13 | C15: United States | D15: ADM | E15: Capture | F15: 2022 | J15: Planned | N15: Biofuels | O15: Dedicated storage | P15: Mt Simon Hub CCS Pipeline (IA) | Q15: North America | R15: https://www.businesswire.com/news/home/20220110006079/en/ | Y15: =IF(CCUS_Projects_Database!$R15<>"",HYPERLINK(CCUS_Projects_Database!$R15,"Link 1"),"") -> Link 1 | Z15: =IF(CCUS_Projects_Database!$S15<>"",HYPERLINK(CCUS_Projects_Database!$S15,"Link 2"),"") | AA15: =IF(CCUS_Projects_Database!$T15<>"",HYPERLINK(CCUS_Projects_Database!$T15,"Link 3"),"") | AB15: =IF(CCUS_Projects_Database!$U15<>"",HYPERLINK(CCUS_Projects_Database!$U15,"Link 4"),"") | AC15: =IF(CCUS_Projects_Database!$V15<>"",HYPERLINK(CCUS_Projects_Database!$V15,"Link 5"),"") | AD15: =IF(CCUS_Projects_Database!$W15<>"",HYPERLINK(CCUS_Projects_Database!$W15,"Link 6"),"") | AE15: =IF(CCUS_Projects_Database!$X15<>"",HYPERLINK(CCUS_Projects_Database!$X15,"Link 7"),"")
A16: ADM Clinton bioethanol (IA) | B16: 14 | C16: United States | D16: ADM | E16: Capture | F16: 2022 | J16: Planned | N16: Biofuels | O16: Dedicated storage | P16: Mt Simon Hub CCS Pipeline (IA) | Q16: North America | R16: https://www.businesswire.com/news/home/20220110006079/en/ | Y16: =IF(CCUS_Projects_Database!$R16<>"",HYPERLINK(CCUS_Projects_Database!$R16,"Link 1"),"") -> Link 1 | Z16: =IF(CCUS_Projects_Database!$S16<>"",HYPERLINK(CCUS_Projects_Database!$S16,"Link 2"),"") | AA16: =IF(CCUS_Projects_Database!$T16<>"",HYPERLINK(CCUS_Projects_Database!$T16,"Link 3"),"") | AB16: =IF(CCUS_Projects_Database!$U16<>"",HYPERLINK(CCUS_Projects_Database!$U16,"Link 4"),"") | AC16: =IF(CCUS_Projects_Database!$V16<>"",HYPERLINK(CCUS_Projects_Database!$V16,"Link 5"),"") | AD16: =IF(CCUS_Projects_Database!$W16<>"",HYPERLINK(CCUS_Projects_Database!$W16,"Link 6"),"") | AE16: =IF(CCUS_Projects_Database!$X16<>"",HYPERLINK(CCUS_Projects_Database!$X16,"Link 7"),"")
A17: ADM Decatur Campus CO2 Storage Site Expansion (IL) | B17: 816 | C17: United States | D17: ADM | E17: T&S | F17: 2022 | H17: 2028 | J17: Planned | K17: 2 | L17: 2.95 | M17: 2.95 | N17: T&S | O17: Dedicated storage | P17: ADM Decatur Campus CO2 Storage Site Expansion (IL) | Q17: North America | Y17: =IF(CCUS_Projects_Database!$R17<>"",HYPERLINK(CCUS_Projects_Database!$R17,"Link 1"),"") | Z17: =IF(CCUS_Projects_Database!$S17<>"",HYPERLINK(CCUS_Projects_Database!$S17,"Link 2"),"") | AA17: =IF(CCUS_Projects_Database!$T17<>"",HYPERLINK(CCUS_Projects_Database!$T17,"Link 3"),"") | AB17: =IF(CCUS_Projects_Database!$U17<>"",HYPERLINK(CCUS_Projects_Database!$U17,"Link 4"),"") | AC17: =IF(CCUS_Projects_Database!$V17<>"",HYPERLINK(CCUS_Projects_Database!$V17,"Link 5"),"") | AD17: =IF(CCUS_Projects_Database!$W17<>"",HYPERLINK(CCUS_Projects_Database!$W17,"Link 6"),"") | AE17: =IF(CCUS_Projects_Database!$X17<>"",HYPERLINK(CCUS_Projects_Database!$X17,"Link 7"),"")
A18: ADM Maroa/Forsyth CO2 Storage Site Development (IL) | B18: 869 | C18: United States | D18: ADM | E18: Storage | F18: 2023 | H18: 2028 | J18: Planned | L18: 3.3 | M18: 3.3 | N18: Storage | O18: Unknown/unspecified | P18: Maroa (IL) | Q18: North America | R18: https://www.epa.gov/uic/current-class-vi-projects-under-review-epa | Y18: =IF(CCUS_Projects_Database!$R18<>"",HYPERLINK(CCUS_Projects_Database!$R18,"Link 1"),"") -> Link 1 | Z18: =IF(CCUS_Projects_Database!$S18<>"",HYPERLINK(CCUS_Projects_Database!$S18,"Link 2"),"") | AA18: =IF(CCUS_Projects_Database!$T18<>"",HYPERLINK(CCUS_Projects_Database!$T18,"Link 3"),"") | AB18: =IF(CCUS_Projects_Database!$U18<>"",HYPERLINK(CCUS_Projects_Database!$U18,"Link 4"),"") | AC18: =IF(CCUS_Projects_Database!$V18<>"",HYPERLINK(CCUS_Projects_Database!$V18,"Link 5"),"") | AD18: =IF(CCUS_Projects_Database!$W18<>"",HYPERLINK(CCUS_Projects_Database!$W18,"Link 6"),"") | AE18: =IF(CCUS_Projects_Database!$X18<>"",HYPERLINK(CCUS_Projects_Database!$X18,"Link 7"),"")
A19: ADNOC CO2 storage hub (Phase 2 of fertiglobe pilot) | B19: 928 | C19: United Arab Emirates | D19: ADNOC | E19: Storage | F19: 2023 | H19: 2030 | J19: Planned | K19: 2 | L19: 5 | M19: 5 | N19: Storage | O19: Dedicated storage | P19: ADNOC CO2 storage hub | Q19: Middle East | R19: https://www.adnoc.ae/en/news-and-media/press-releases/2023/adnoc-announces-world-first-fully-sequestered-co2-injection-project | Y19: =IF(CCUS_Projects_Database!$R19<>"",HYPERLINK(CCUS_Projects_Database!$R19,"Link 1"),"") -> Link 1 | Z19: =IF(CCUS_Projects_Database!$S19<>"",HYPERLINK(CCUS_Projects_Database!$S19,"Link 2"),"") | AA19: =IF(CCUS_Projects_Database!$T19<>"",HYPERLINK(CCUS_Projects_Database!$T19,"Link 3"),"") | AB19: =IF(CCUS_Projects_Database!$U19<>"",HYPERLINK(CCUS_Projects_Database!$U19,"Link 4"),"") | AC19: =IF(CCUS_Projects_Database!$V19<>"",HYPERLINK(CCUS_Projects_Database!$V19,"Link 5"),"") | AD19: =IF(CCUS_Projects_Database!$W19<>"",HYPERLINK(CCUS_Projects_Database!$W19,"Link 6"),"") | AE19: =IF(CCUS_Projects_Database!$X19<>"",HYPERLINK(CCUS_Projects_Database!$X19,"Link 7"),"")
A20: Advanced CO2 Capture from Hydrogen Production Unit at Phillips 66 Rodeo Refinery (CA) | B20: 695 | C20: United States | D20: Phillips 66 | E20: Capture | F20: 2021 | J20: Planned | L20: 0.19 | M20: 0.19 | N20: Other fuel transformation | O20: Unknown/unspecified | Q20: North America | R20: https://www.netl.doe.gov/node/10875 | Y20: =IF(CCUS_Projects_Database!$R20<>"",HYPERLINK(CCUS_Projects_Database!$R20,"Link 1"),"") -> Link 1 | Z20: =IF(CCUS_Projects_Database!$S20<>"",HYPERLINK(CCUS_Projects_Database!$S20,"Link 2"),"") | AA20: =IF(CCUS_Projects_Database!$T20<>"",HYPERLINK(CCUS_Projects_Database!$T20,"Link 3"),"") | AB20: =IF(CCUS_Projects_Database!$U20<>"",HYPERLINK(CCUS_Projects_Database!$U20,"Link 4"),"") | AC20: =IF(CCUS_Projects_Database!$V20<>"",HYPERLINK(CCUS_Projects_Database!$V20,"Link 5"),"") | AD20: =IF(CCUS_Projects_Database!$W20<>"",HYPERLINK(CCUS_Projects_Database!$W20,"Link 6"),"") | AE20: =IF(CCUS_Projects_Database!$X20<>"",HYPERLINK(CCUS_Projects_Database!$X20,"Link 7"),"")
A21: AEB Amsterdam | B21: 1144 | C21: Netherlands | D21: AEB Amsterdam | E21: CCU | F21: 2021 | H21: 2028 | J21: Planned | L21: 0.44 | M21: 0.44 | N21: Power and heat | O21: Use | Q21: Europe | R21: https://www.kn.lt/en/news/news/kn-akmenes-cementas-and-orlen-lietuva-to-evaluate-the-applicability-of-liquefied-co2-capture-technology/5686 | S21: https://www.aebamsterdam.com/technology/ | Y21: =IF(CCUS_Projects_Database!$R21<>"",HYPERLINK(CCUS_Projects_Database!$R21,"Link 1"),"") -> Link 1 | Z21: =IF(CCUS_Projects_Database!$S21<>"",HYPERLINK(CCUS_Projects_Database!$S21,"Link 2"),"") -> Link 2 | AA21: =IF(CCUS_Projects_Database!$T21<>"",HYPERLINK(CCUS_Projects_Database!$T21,"Link 3"),"") | AB21: =IF(CCUS_Projects_Database!$U21<>"",HYPERLINK(CCUS_Projects_Database!$U21,"Link 4"),"") | AC21: =IF(CCUS_Projects_Database!$V21<>"",HYPERLINK(CCUS_Projects_Database!$V21,"Link 5"),"") | AD21: =IF(CCUS_Projects_Database!$W21<>"",HYPERLINK(CCUS_Projects_Database!$W21,"Link 6"),"") | AE21: =IF(CCUS_Projects_Database!$X21<>"",HYPERLINK(CCUS_Projects_Database!$X21,"Link 7"),"")
A22: Aemetis CCS (CA) | B22: 814 | C22: United States | D22: Aemetis Carbon Capture (Aemetis) | E22: Storage | F22: 2021 | H22: 2024 | J22: Planned | L22: 1.7 | M22: 1.4 | N22: Storage | O22: Dedicated storage | P22: Aemetis CCS | Q22: North America | R22: https://www.aemetis.com/products/carbon-capture/ | S22: https://www.aemetis.com/aemetis-awarded-the-first-co2-sequestration-characterization-well-permit-issued-by-the-state-of-california/ | Y22: =IF(CCUS_Projects_Database!$R22<>"",HYPERLINK(CCUS_Projects_Database!$R22,"Link 1"),"") -> Link 1 | Z22: =IF(CCUS_Projects_Database!$S22<>"",HYPERLINK(CCUS_Projects_Database!$S22,"Link 2"),"") -> Link 2 | AA22: =IF(CCUS_Projects_Database!$T22<>"",HYPERLINK(CCUS_Projects_Database!$T22,"Link 3"),"") | AB22: =IF(CCUS_Projects_Database!$U22<>"",HYPERLINK(CCUS_Projects_Database!$U22,"Link 4"),"") | AC22: =IF(CCUS_Projects_Database!$V22<>"",HYPERLINK(CCUS_Projects_Database!$V22,"Link 5"),"") | AD22: =IF(CCUS_Projects_Database!$W22<>"",HYPERLINK(CCUS_Projects_Database!$W22,"Link 6"),"") | AE22: =IF(CCUS_Projects_Database!$X22<>"",HYPERLINK(CCUS_Projects_Database!$X22,"Link 7"),"")
A23: Aemetis CCS Keyes facility (CA) | B23: 15 | C23: United States | D23: Aemetis | E23: Capture | F23: 2021 | H23: 2024 | J23: Planned | L23: 0.2 | M23: 0.2 | N23: Biofuels | O23: Dedicated storage | P23: Aemetis CCS | Q23: North America | R23: https://www.globenewswire.com/news-release/2021/08/18/2282675/0/en/Aemetis-CCS-Drilling-Study-by-Baker-Hughes-Confirms-Feasibility-of-Sequestering-Two-Million-MT-per-Year-of-CO2-at-California-Ethanol-Plant-Sites.html | S23: https://www.aemetis.com/products/carbon-capture/ | T23: https://www.aemetis.com/products/carbon-capture/ | U23: https://www.aemetis.com/aemetis-awarded-the-first-co2-sequestration-characterization-well-permit-issued-by-the-state-of-california/ | Y23: =IF(CCUS_Projects_Database!$R23<>"",HYPERLINK(CCUS_Projects_Database!$R23,"Link 1"),"") -> Link 1 | Z23: =IF(CCUS_Projects_Database!$S23<>"",HYPERLINK(CCUS_Projects_Database!$S23,"Link 2"),"") -> Link 2 | AA23: =IF(CCUS_Projects_Database!$T23<>"",HYPERLINK(CCUS_Projects_Database!$T23,"Link 3"),"") -> Link 3 | AB23: =IF(CCUS_Projects_Database!$U23<>"",HYPERLINK(CCUS_Projects_Database!$U23,"Link 4"),"") -> Link 4 | AC23: =IF(CCUS_Projects_Database!$V23<>"",HYPERLINK(CCUS_Projects_Database!$V23,"Link 5"),"") | AD23: =IF(CCUS_Projects_Database!$W23<>"",HYPERLINK(CCUS_Projects_Database!$W23,"Link 6"),"") | AE23: =IF(CCUS_Projects_Database!$X23<>"",HYPERLINK(CCUS_Projects_Database!$X23,"Link 7"),"")
A24: Aemetis CCS Riverbank facility (CA) | B24: 16 | C24: United States | D24: Aemetis | E24: Capture | F24: 2021 | H24: 2024 | J24: Planned | L24: 0.2 | M24: 0.2 | N24: Biofuels | O24: Dedicated storage | P24: Aemetis CCS | Q24: North America | R24: https://www.globenewswire.com/news-release/2021/08/18/2282675/0/en/Aemetis-CCS-Drilling-Study-by-Baker-Hughes-Confirms-Feasibility-of-Sequestering-Two-Million-MT-per-Year-of-CO2-at-California-Ethanol-Plant-Sites.html | S24: https://www.aemetis.com/products/carbon-capture/ | T24: https://www.aemetis.com/products/carbon-capture/ | U24: https://www.aemetis.com/aemetis-awarded-the-first-co2-sequestration-characterization-well-permit-issued-by-the-state-of-california/ | Y24: =IF(CCUS_Projects_Database!$R24<>"",HYPERLINK(CCUS_Projects_Database!$R24,"Link 1"),"") -> Link 1 | Z24: =IF(CCUS_Projects_Database!$S24<>"",HYPERLINK(CCUS_Projects_Database!$S24,"Link 2"),"") -> Link 2 | AA24: =IF(CCUS_Projects_Database!$T24<>"",HYPERLINK(CCUS_Projects_Database!$T24,"Link 3"),"") -> Link 3 | AB24: =IF(CCUS_Projects_Database!$U24<>"",HYPERLINK(CCUS_Projects_Database!$U24,"Link 4"),"") -> Link 4 | AC24: =IF(CCUS_Projects_Database!$V24<>"",HYPERLINK(CCUS_Projects_Database!$V24,"Link 5"),"") | AD24: =IF(CCUS_Projects_Database!$W24<>"",HYPERLINK(CCUS_Projects_Database!$W24,"Link 6"),"") | AE24: =IF(CCUS_Projects_Database!$X24<>"",HYPERLINK(CCUS_Projects_Database!$X24,"Link 7"),"")
A25: Air Liquide hydrogen facility Rotterdam | B25: 18 | C25: Netherlands | D25: Air Liquide (build, own, operate) | E25: Capture | F25: 2012 | G25: 2023 | H25: 2026 | J25: Under construction | L25: 0.5 | M25: 0.5 | N25: Other fuel transformation | O25: Dedicated storage | P25: Porthos | Q25: Europe | R25: https://netherlandsnewslive.com/the-botlek-oil-industry-wants-2-1-billion-euros-for-co2-storage/62256/ | S25: https://www.pbl.nl/sites/default/files/downloads/pbl-2022-decarbonisation-of-the-industry-cluster-botlek-pernis-rotterdam-4946.pdf | T25: https://www.airliquide.com/group/press-releases-news/2023-12-19/air-liquide-build-world-scale-co2-capture-unit-contribute-rotterdams-industrial-basin | U25: https://www.hydrogeninsight.com/production/second-major-blue-hydrogen-project-reaches-final-investment-decision-in-rotterdam/2-1-1574743 | Y25: =IF(CCUS_Projects_Database!$R25<>"",HYPERLINK(CCUS_Projects_Database!$R25,"Link 1"),"") -> Link 1 | Z25: =IF(CCUS_Projects_Database!$S25<>"",HYPERLINK(CCUS_Projects_Database!$S25,"Link 2"),"") -> Link 2 | AA25: =IF(CCUS_Projects_Database!$T25<>"",HYPERLINK(CCUS_Projects_Database!$T25,"Link 3"),"") -> Link 3 | AB25: =IF(CCUS_Projects_Database!$U25<>"",HYPERLINK(CCUS_Projects_Database!$U25,"Link 4"),"") -> Link 4 | AC25: =IF(CCUS_Projects_Database!$V25<>"",HYPERLINK(CCUS_Projects_Database!$V25,"Link 5"),"") | AD25: =IF(CCUS_Projects_Database!$W25<>"",HYPERLINK(CCUS_Projects_Database!$W25,"Link 6"),"") | AE25: =IF(CCUS_Projects_Database!$X25<>"",HYPERLINK(CCUS_Projects_Database!$X25,"Link 7"),"")
A26: Air Liquide Shanghai Chemical Industry Park (SCIP) decarbonisation (Shanghai) | B26: 541 | C26: People's Republic of China | D26: SCIPIG (Air Liquide) | E26: Capture | F26: 2022 | H26: 2028 | J26: Planned | N26: Hydrogen or ammonia | O26: Unknown/unspecified | Q26: Other Asia Pacific | R26: https://www.airliquide.com/group/press-releases-news/2022-07-19/air-liquide-build-two-new-hydrogen-production-units-carbon-capture-technology-shanghai-chemical | S26: https://www.businesswire.com/news/home/20230718825639/en/Air-Liquide-signs-new-green-financing-for-low-carbon-hydrogen-production-in-China-aligned-with-EU-Taxonomy | Y26: =IF(CCUS_Projects_Database!$R26<>"",HYPERLINK(CCUS_Projects_Database!$R26,"Link 1"),"") -> Link 1 | Z26: =IF(CCUS_Projects_Database!$S26<>"",HYPERLINK(CCUS_Projects_Database!$S26,"Link 2"),"") -> Link 2 | AA26: =IF(CCUS_Projects_Database!$T26<>"",HYPERLINK(CCUS_Projects_Database!$T26,"Link 3"),"") | AB26: =IF(CCUS_Projects_Database!$U26<>"",HYPERLINK(CCUS_Projects_Database!$U26,"Link 4"),"") | AC26: =IF(CCUS_Projects_Database!$V26<>"",HYPERLINK(CCUS_Projects_Database!$V26,"Link 5"),"") | AD26: =IF(CCUS_Projects_Database!$W26<>"",HYPERLINK(CCUS_Projects_Database!$W26,"Link 6"),"") | AE26: =IF(CCUS_Projects_Database!$X26<>"",HYPERLINK(CCUS_Projects_Database!$X26,"Link 7"),"")
A27: Air Products for Exxonmobil Botlek Rotterdam refinery | B27: 150 | C27: Netherlands | D27: Exxonmobil, Air Products | E27: Capture | F27: 2019 | G27: 2023 | H27: 2026 | J27: Under construction | M27: 1.011 | N27: Other fuel transformation | O27: Dedicated storage | P27: Porthos | Q27: Europe | R27: https://netherlandsnewslive.com/the-botlek-oil-industry-wants-2-1-billion-euros-for-co2-storage/62256/ | S27: https://www.airproducts.com/company/news-center/2023/11/1106-air-products-blue-hydrogen-plant-europe-and-exxonmobil-long-term-agreement | T27: https://www.hydrogeninsight.com/production/largest-in-europe-air-products-announces-blue-hydrogen-plant-at-rotterdam-linked-to-dutch-offshore-ccs-network/2-1-1549667 | Y27: =IF(CCUS_Projects_Database!$R27<>"",HYPERLINK(CCUS_Projects_Database!$R27,"Link 1"),"") -> Link 1 | Z27: =IF(CCUS_Projects_Database!$S27<>"",HYPERLINK(CCUS_Projects_Database!$S27,"Link 2"),"") -> Link 2 | AA27: =IF(CCUS_Projects_Database!$T27<>"",HYPERLINK(CCUS_Projects_Database!$T27,"Link 3"),"") -> Link 3 | AB27: =IF(CCUS_Projects_Database!$U27<>"",HYPERLINK(CCUS_Projects_Database!$U27,"Link 4"),"") | AC27: =IF(CCUS_Projects_Database!$V27<>"",HYPERLINK(CCUS_Projects_Database!$V27,"Link 5"),"") | AD27: =IF(CCUS_Projects_Database!$W27<>"",HYPERLINK(CCUS_Projects_Database!$W27,"Link 6"),"") | AE27: =IF(CCUS_Projects_Database!$X27<>"",HYPERLINK(CCUS_Projects_Database!$X27,"Link 7"),"")
A28: AirCapture DACU at Nutrien Kennewick Fertilizer (WA) | B28: 21 | C28: United States | D28: AirCapture, Nutrien | E28: CCU | F28: 2022 | J28: Planned | N28: DAC | O28: Use | Q28: North America | R28: https://www.energy.gov/fecm/articles/selections-funding-opportunity-announcement-2560-direct-air-capture-combined | Y28: =IF(CCUS_Projects_Database!$R28<>"",HYPERLINK(CCUS_Projects_Database!$R28,"Link 1"),"") -> Link 1 | Z28: =IF(CCUS_Projects_Database!$S28<>"",HYPERLINK(CCUS_Projects_Database!$S28,"Link 2"),"") | AA28: =IF(CCUS_Projects_Database!$T28<>"",HYPERLINK(CCUS_Projects_Database!$T28,"Link 3"),"") | AB28: =IF(CCUS_Projects_Database!$U28<>"",HYPERLINK(CCUS_Projects_Database!$U28,"Link 4"),"") | AC28: =IF(CCUS_Projects_Database!$V28<>"",HYPERLINK(CCUS_Projects_Database!$V28,"Link 5"),"") | AD28: =IF(CCUS_Projects_Database!$W28<>"",HYPERLINK(CCUS_Projects_Database!$W28,"Link 6"),"") | AE28: =IF(CCUS_Projects_Database!$X28<>"",HYPERLINK(CCUS_Projects_Database!$X28,"Link 7"),"")
A29: AirCapture Nuclear DAC at JM Farley Nuclear (AL) | B29: 22 | C29: United States | D29: Southern Company, Battelle, AirCapture LLC | E29: Capture | F29: 2022 | J29: Planned | N29: DAC | O29: Dedicated storage | Q29: North America | R29: https://www.energy.gov/fecm/articles/selections-funding-opportunity-announcement-2560-direct-air-capture-combined | S29: https://www.power-eng.com/emissions/doe-funds-direct-air-capture-project-at-alabama-nuclear-plant/ | Y29: =IF(CCUS_Projects_Database!$R29<>"",HYPERLINK(CCUS_Projects_Database!$R29,"Link 1"),"") -> Link 1 | Z29: =IF(CCUS_Projects_Database!$S29<>"",HYPERLINK(CCUS_Projects_Database!$S29,"Link 2"),"") -> Link 2 | AA29: =IF(CCUS_Projects_Database!$T29<>"",HYPERLINK(CCUS_Projects_Database!$T29,"Link 3"),"") | AB29: =IF(CCUS_Projects_Database!$U29<>"",HYPERLINK(CCUS_Projects_Database!$U29,"Link 4"),"") | AC29: =IF(CCUS_Projects_Database!$V29<>"",HYPERLINK(CCUS_Projects_Database!$V29,"Link 5"),"") | AD29: =IF(CCUS_Projects_Database!$W29<>"",HYPERLINK(CCUS_Projects_Database!$W29,"Link 6"),"") | AE29: =IF(CCUS_Projects_Database!$X29<>"",HYPERLINK(CCUS_Projects_Database!$X29,"Link 7"),"")
A30: Airhive Alpha Lab pilot | B30: 952 | C30: Canada | D30: Airhive, Deep Sky | E30: CCU | F30: 2023 | H30: 2024 | J30: Planned | L30: 0.001 | M30: 0.001 | N30: DAC | O30: Use | Q30: North America | R30: https://airhive.earth/news/deep-sky-airhive-collab | Y30: =IF(CCUS_Projects_Database!$R30<>"",HYPERLINK(CCUS_Projects_Database!$R30,"Link 1"),"") -> Link 1 | Z30: =IF(CCUS_Projects_Database!$S30<>"",HYPERLINK(CCUS_Projects_Database!$S30,"Link 2"),"") | AA30: =IF(CCUS_Projects_Database!$T30<>"",HYPERLINK(CCUS_Projects_Database!$T30,"Link 3"),"") | AB30: =IF(CCUS_Projects_Database!$U30<>"",HYPERLINK(CCUS_Projects_Database!$U30,"Link 4"),"") | AC30: =IF(CCUS_Projects_Database!$V30<>"",HYPERLINK(CCUS_Projects_Database!$V30,"Link 5"),"") | AD30: =IF(CCUS_Projects_Database!$W30<>"",HYPERLINK(CCUS_Projects_Database!$W30,"Link 6"),"") | AE30: =IF(CCUS_Projects_Database!$X30<>"",HYPERLINK(CCUS_Projects_Database!$X30,"Link 7"),"")
A31: Aittaluoto power (Pori) | B31: 1032 | C31: Finland | D31: RenGas, Pori Energia | E31: CCU | F31: 2022 | G31: 2025 | H31: 2027 | J31: Planned | L31: 0.1 | M31: 0.1 | N31: Power and heat | O31: Use | Q31: Europe | R31: https://ren-gas.com/en/projekti/pori-2/ | Y31: =IF(CCUS_Projects_Database!$R31<>"",HYPERLINK(CCUS_Projects_Database!$R31,"Link 1"),"") -> Link 1 | Z31: =IF(CCUS_Projects_Database!$S31<>"",HYPERLINK(CCUS_Projects_Database!$S31,"Link 2"),"") | AA31: =IF(CCUS_Projects_Database!$T31<>"",HYPERLINK(CCUS_Projects_Database!$T31,"Link 3"),"") | AB31: =IF(CCUS_Projects_Database!$U31<>"",HYPERLINK(CCUS_Projects_Database!$U31,"Link 4"),"") | AC31: =IF(CCUS_Projects_Database!$V31<>"",HYPERLINK(CCUS_Projects_Database!$V31,"Link 5"),"") | AD31: =IF(CCUS_Projects_Database!$W31<>"",HYPERLINK(CCUS_Projects_Database!$W31,"Link 6"),"") | AE31: =IF(CCUS_Projects_Database!$X31<>"",HYPERLINK(CCUS_Projects_Database!$X31,"Link 7"),"")
A32: Aker CC Biomass CHP (unknown facility) | B32: 1099 | C32: Germany | D32: Aker CC, unknown company | E32: Capture | F32: 2023 | J32: Planned | L32: 0.25 | M32: 0.25 | N32: Power and heat | O32: Unknown/unspecified | Q32: Europe | R32: https://akercarboncapture.com/?cision_id=4338F917D2B89C6E | Y32: =IF(CCUS_Projects_Database!$R32<>"",HYPERLINK(CCUS_Projects_Database!$R32,"Link 1"),"") -> Link 1 | Z32: =IF(CCUS_Projects_Database!$S32<>"",HYPERLINK(CCUS_Projects_Database!$S32,"Link 2"),"") | AA32: =IF(CCUS_Projects_Database!$T32<>"",HYPERLINK(CCUS_Projects_Database!$T32,"Link 3"),"") | AB32: =IF(CCUS_Projects_Database!$U32<>"",HYPERLINK(CCUS_Projects_Database!$U32,"Link 4"),"") | AC32: =IF(CCUS_Projects_Database!$V32<>"",HYPERLINK(CCUS_Projects_Database!$V32,"Link 5"),"") | AD32: =IF(CCUS_Projects_Database!$W32<>"",HYPERLINK(CCUS_Projects_Database!$W32,"Link 6"),"") | AE32: =IF(CCUS_Projects_Database!$X32<>"",HYPERLINK(CCUS_Projects_Database!$X32,"Link 7"),"")
A33: Aker CC mineral production (unknown facilities) | B33: 920 | C33: United States | D33: Aker CC, unknown company | E33: Capture | F33: 2023 | J33: Planned | L33: 1.5 | M33: 1.5 | N33: Cement | O33: Unknown/unspecified | Q33: North America | R33: https://akercarboncapture.com/?cision_id=C8E822C2D97A90E2 | Y33: =IF(CCUS_Projects_Database!$R33<>"",HYPERLINK(CCUS_Projects_Database!$R33,"Link 1"),"") -> Link 1 | Z33: =IF(CCUS_Projects_Database!$S33<>"",HYPERLINK(CCUS_Projects_Database!$S33,"Link 2"),"") | AA33: =IF(CCUS_Projects_Database!$T33<>"",HYPERLINK(CCUS_Projects_Database!$T33,"Link 3"),"") | AB33: =IF(CCUS_Projects_Database!$U33<>"",HYPERLINK(CCUS_Projects_Database!$U33,"Link 4"),"") | AC33: =IF(CCUS_Projects_Database!$V33<>"",HYPERLINK(CCUS_Projects_Database!$V33,"Link 5"),"") | AD33: =IF(CCUS_Projects_Database!$W33<>"",HYPERLINK(CCUS_Projects_Database!$W33,"Link 6"),"") | AE33: =IF(CCUS_Projects_Database!$X33<>"",HYPERLINK(CCUS_Projects_Database!$X33,"Link 7"),"")
A34: Aker CC power plant Europe (unknown facilities) | B34: 1097 | C34: Unknown | D34: Aker CC, unknown company | E34: Capture | F34: 2023 | J34: Planned | L34: 14 | M34: 14 | N34: Power and heat | O34: Unknown/unspecified | Q34: Unknown | R34: https://akercarboncapture.com/?cision_id=42ED18602F06D910 | Y34: =IF(CCUS_Projects_Database!$R34<>"",HYPERLINK(CCUS_Projects_Database!$R34,"Link 1"),"") -> Link 1 | Z34: =IF(CCUS_Projects_Database!$S34<>"",HYPERLINK(CCUS_Projects_Database!$S34,"Link 2"),"") | AA34: =IF(CCUS_Projects_Database!$T34<>"",HYPERLINK(CCUS_Projects_Database!$T34,"Link 3"),"") | AB34: =IF(CCUS_Projects_Database!$U34<>"",HYPERLINK(CCUS_Projects_Database!$U34,"Link 4"),"") | AC34: =IF(CCUS_Projects_Database!$V34<>"",HYPERLINK(CCUS_Projects_Database!$V34,"Link 5"),"") | AD34: =IF(CCUS_Projects_Database!$W34<>"",HYPERLINK(CCUS_Projects_Database!$W34,"Link 6"),"") | AE34: =IF(CCUS_Projects_Database!$X34<>"",HYPERLINK(CCUS_Projects_Database!$X34,"Link 7"),"")
A35: Aker CC refinery (unknown facility) | B35: 1103 | C35: United States | D35: Aker CC, unknown company | E35: Capture | F35: 2023 | J35: Planned | L35: 1.2 | M35: 1.2 | N35: Other fuel transformation | O35: Unknown/unspecified | Q35: North America | Y35: =IF(CCUS_Projects_Database!$R35<>"",HYPERLINK(CCUS_Projects_Database!$R35,"Link 1"),"") | Z35: =IF(CCUS_Projects_Database!$S35<>"",HYPERLINK(CCUS_Projects_Database!$S35,"Link 2"),"") | AA35: =IF(CCUS_Projects_Database!$T35<>"",HYPERLINK(CCUS_Projects_Database!$T35,"Link 3"),"") | AB35: =IF(CCUS_Projects_Database!$U35<>"",HYPERLINK(CCUS_Projects_Database!$U35,"Link 4"),"") | AC35: =IF(CCUS_Projects_Database!$V35<>"",HYPERLINK(CCUS_Projects_Database!$V35,"Link 5"),"") | AD35: =IF(CCUS_Projects_Database!$W35<>"",HYPERLINK(CCUS_Projects_Database!$W35,"Link 6"),"") | AE35: =IF(CCUS_Projects_Database!$X35<>"",HYPERLINK(CCUS_Projects_Database!$X35,"Link 7"),"")
A36: Aker CC Swedish energy company (unknown) | B36: 1100 | C36: Sweden | D36: Aker CC, unknown company | E36: Capture | F36: 2023 | J36: Planned | L36: 0.2 | M36: 0.2 | N36: Power and heat | O36: Unknown/unspecified | Q36: Europe | Y36: =IF(CCUS_Projects_Database!$R36<>"",HYPERLINK(CCUS_Projects_Database!$R36,"Link 1"),"") | Z36: =IF(CCUS_Projects_Database!$S36<>"",HYPERLINK(CCUS_Projects_Database!$S36,"Link 2"),"") | AA36: =IF(CCUS_Projects_Database!$T36<>"",HYPERLINK(CCUS_Projects_Database!$T36,"Link 3"),"") | AB36: =IF(CCUS_Projects_Database!$U36<>"",HYPERLINK(CCUS_Projects_Database!$U36,"Link 4"),"") | AC36: =IF(CCUS_Projects_Database!$V36<>"",HYPERLINK(CCUS_Projects_Database!$V36,"Link 5"),"") | AD36: =IF(CCUS_Projects_Database!$W36<>"",HYPERLINK(CCUS_Projects_Database!$W36,"Link 6"),"") | AE36: =IF(CCUS_Projects_Database!$X36<>"",HYPERLINK(CCUS_Projects_Database!$X36,"Link 7"),"")
A37: Aker CC waste to energy Northern Europe (unknown facility) | B37: 1102 | C37: Unknown | D37: Aker CC, unknown company | E37: Capture | F37: 2024 | J37: Planned | N37: Power and heat | O37: Unknown/unspecified | Q37: Europe | R37: https://akercarboncapture.com/?cision_id=3538EFD96277831D | Y37: =IF(CCUS_Projects_Database!$R37<>"",HYPERLINK(CCUS_Projects_Database!$R37,"Link 1"),"") -> Link 1 | Z37: =IF(CCUS_Projects_Database!$S37<>"",HYPERLINK(CCUS_Projects_Database!$S37,"Link 2"),"") | AA37: =IF(CCUS_Projects_Database!$T37<>"",HYPERLINK(CCUS_Projects_Database!$T37,"Link 3"),"") | AB37: =IF(CCUS_Projects_Database!$U37<>"",HYPERLINK(CCUS_Projects_Database!$U37,"Link 4"),"") | AC37: =IF(CCUS_Projects_Database!$V37<>"",HYPERLINK(CCUS_Projects_Database!$V37,"Link 5"),"") | AD37: =IF(CCUS_Projects_Database!$W37<>"",HYPERLINK(CCUS_Projects_Database!$W37,"Link 6"),"") | AE37: =IF(CCUS_Projects_Database!$X37<>"",HYPERLINK(CCUS_Projects_Database!$X37,"Link 7"),"")
A38: Aker CC WtE e-fuels | B38: 1098 | C38: Finland | D38: Aker CC, unknown company | E38: CCU | F38: 2023 | J38: Planned | L38: 0.1 | M38: 0.1 | N38: Power and heat | O38: Use | Q38: Europe | R38: https://akercarboncapture.com/?cision_id=4676790745A256E2 | Y38: =IF(CCUS_Projects_Database!$R38<>"",HYPERLINK(CCUS_Projects_Database!$R38,"Link 1"),"") -> Link 1 | Z38: =IF(CCUS_Projects_Database!$S38<>"",HYPERLINK(CCUS_Projects_Database!$S38,"Link 2"),"") | AA38: =IF(CCUS_Projects_Database!$T38<>"",HYPERLINK(CCUS_Projects_Database!$T38,"Link 3"),"") | AB38: =IF(CCUS_Projects_Database!$U38<>"",HYPERLINK(CCUS_Projects_Database!$U38,"Link 4"),"") | AC38: =IF(CCUS_Projects_Database!$V38<>"",HYPERLINK(CCUS_Projects_Database!$V38,"Link 5"),"") | AD38: =IF(CCUS_Projects_Database!$W38<>"",HYPERLINK(CCUS_Projects_Database!$W38,"Link 6"),"") | AE38: =IF(CCUS_Projects_Database!$X38<>"",HYPERLINK(CCUS_Projects_Database!$X38,"Link 7"),"")
A39: Alaska Railbelt CCS Project (AK) | B39: 976 | C39: United States | D39: University of Alaska Fairbanks | E39: Storage | F39: 2023 | J39: Planned | N39: Storage | O39: Dedicated storage | P39: Alaska Railbelt CCS Project (AK) | Q39: North America | R39: https://www.energy.gov/fecm/project-selections-foa-2711-carbon-storage-validation-and-testing-round-2 | Y39: =IF(CCUS_Projects_Database!$R39<>"",HYPERLINK(CCUS_Projects_Database!$R39,"Link 1"),"") -> Link 1 | Z39: =IF(CCUS_Projects_Database!$S39<>"",HYPERLINK(CCUS_Projects_Database!$S39,"Link 2"),"") | AA39: =IF(CCUS_Projects_Database!$T39<>"",HYPERLINK(CCUS_Projects_Database!$T39,"Link 3"),"") | AB39: =IF(CCUS_Projects_Database!$U39<>"",HYPERLINK(CCUS_Projects_Database!$U39,"Link 4"),"") | AC39: =IF(CCUS_Projects_Database!$V39<>"",HYPERLINK(CCUS_Projects_Database!$V39,"Link 5"),"") | AD39: =IF(CCUS_Projects_Database!$W39<>"",HYPERLINK(CCUS_Projects_Database!$W39,"Link 6"),"") | AE39: =IF(CCUS_Projects_Database!$X39<>"",HYPERLINK(CCUS_Projects_Database!$X39,"Link 7"),"")
A40: Alberta Carbon Grid (ALB) phase 1 (Industrial heartland) | B40: 24 | C40: Canada | D40: Pembina Pipeline Corporation, TC Energy | E40: T&S | F40: 2021 | G40: 2025 | H40: 2027 | J40: Planned | L40: 10 | M40: 10 | N40: T&S | O40: Dedicated storage | P40: Alberta Carbon Grid (ALB) | Q40: North America | R40: https://albertacarbongrid.ca/ | S40: https://albertacarbongrid.ca/news/acg-secures-rights-to-evaluate-one-of-the-largest-carbon-storage-areas-in-alberta/ | Y40: =IF(CCUS_Projects_Database!$R40<>"",HYPERLINK(CCUS_Projects_Database!$R40,"Link 1"),"") -> Link 1 | Z40: =IF(CCUS_Projects_Database!$S40<>"",HYPERLINK(CCUS_Projects_Database!$S40,"Link 2"),"") -> Link 2 | AA40: =IF(CCUS_Projects_Database!$T40<>"",HYPERLINK(CCUS_Projects_Database!$T40,"Link 3"),"") | AB40: =IF(CCUS_Projects_Database!$U40<>"",HYPERLINK(CCUS_Projects_Database!$U40,"Link 4"),"") | AC40: =IF(CCUS_Projects_Database!$V40<>"",HYPERLINK(CCUS_Projects_Database!$V40,"Link 5"),"") | AD40: =IF(CCUS_Projects_Database!$W40<>"",HYPERLINK(CCUS_Projects_Database!$W40,"Link 6"),"") | AE40: =IF(CCUS_Projects_Database!$X40<>"",HYPERLINK(CCUS_Projects_Database!$X40,"Link 7"),"")
...
